<?xml version="1.0"?>
<robot name="wheel" xmlns:xacro="http://www.ros.org/wiki/xacro">
  
  <!-- Wheels -->
  <property name="wheel_radius" value="0.050" /> 
  <property name="arm_wheel_radius" value="0.0350" /> 
  <property name="wheel_height" value="0.02" />
  <property name="arm_wheel_height" value="0.025" />
  <property name="wheel_mass" value="0.15" /> 
  <property name="arm_wheel_mass" value="0.005" /> 
  
  <property name="base_x_origin_to_wheel_origin" value="-0.110" />
  <property name="base_y_origin_to_wheel_origin" value="0.095" />
  <property name="base_z_origin_to_wheel_origin" value="-0.005" />
  
  <macro name="cylinder_inertia" params="m r h">
    <inertia  ixx="${m*(3*r*r+h*h)/12}" ixy = "0" ixz = "0"
              iyy="${m*(3*r*r+h*h)/12}" iyz = "0"
              izz="${m*r*r/2}" /> 
  </macro>
  
  <xacro:macro name="wheel" params="fb lr parent translateX translateY translateZ flipY"> <!--fb : front, back ; lr: left, right -->
    <link name="${fb}_${lr}_wheel">
      <visual>
        <origin xyz="0 ${flipY*0.01} 0" rpy="${flipY*M_PI/2} 0 ${flipY*M_PI/2}" /> 
        <geometry>
          <mesh filename="package://shadow-bot/meshes/dae/rearWheel.dae"/>
        </geometry>
      </visual>
      <collision>
        <origin xyz="0 ${flipY*0.01} 0" rpy="${flipY*M_PI/2} 0 0 " />
        <geometry>
          <cylinder length="${wheel_height}" radius="${wheel_radius}" />
        </geometry>
        <surface>
          <friction>
            <ode>
              <mu>1.0</mu>
              <mu2>0.25</mu2>
              <fdir1>1 0 0</fdir1>
              <slip1>0</slip1>
              <slip2>0</slip2>
            </ode>
            <torsional>
              <coefficient>0.0</coefficient>
              <patch_radius>0</patch_radius>
              <surface_radius>0</surface_radius>
              <use_patch_radius>1</use_patch_radius>
              <ode>
                <slip>0</slip>
              </ode>
            </torsional>
          </friction>
          <bounce>
            <restitution_coefficient>0</restitution_coefficient>
            <threshold>1e+06</threshold>
          </bounce>
          <contact>
            <collide_without_contact>0</collide_without_contact>
            <collide_without_contact_bitmask>0</collide_without_contact_bitmask>
            <collide_bitmask>0</collide_bitmask>
            <ode>
              <max_vel>0.1</max_vel>
              <soft_cfm>0.8</soft_cfm>
              <soft_erp>0.8</soft_erp>
              <kd>2500</kd>
              <kp>10</kp>
              <min_depth>0.001</min_depth>
            </ode>
            <bullet>
              <split_impulse>1</split_impulse>
              <split_impulse_penetration_threshold>-0.01</split_impulse_penetration_threshold>
              <soft_cfm>0</soft_cfm>
              <soft_erp>0.2</soft_erp>
              <kp>1e+13</kp>
              <kd>1</kd>
            </bullet>
          </contact>     
        </surface>
      </collision>
      <inertial>
        <mass value="${wheel_mass}" />
        <origin xyz="0 0 0" rpy="${flipY*M_PI/2} 0 0 " />
        <cylinder_inertia  m="${wheel_mass}" r="${wheel_radius}" h="${wheel_height}" />
      </inertial>
    </link>

    <gazebo reference="${fb}_${lr}_wheel">
      <turnGravityOff>false</turnGravityOff>
    </gazebo>

    <joint name="${fb}_${lr}_wheel_joint" type="continuous">
      <parent link="${parent}"/>
      <child link="${fb}_${lr}_wheel"/>
      <origin xyz="${translateX} ${translateY} ${translateZ}" rpy="0 0 0" /> 
      <axis xyz="0 1 0" rpy="0  0" />
      <limit effort="100" velocity="100"/>
      <joint_properties damping="0.5" friction="100.0"/>
    </joint>

    <!-- Transmission is important to link the joints and the controller -->
    <transmission name="${fb}_${lr}_wheel_joint_trans">
      <type>transmission_interface/SimpleTransmission</type>
      <joint name="${fb}_${lr}_wheel_joint">
        <hardwareInterface>hardware_interface/EffortJointInterface</hardwareInterface>
      </joint>
      <actuator name="${fb}_${lr}_wheel_joint_motor">
        <hardwareInterface>hardware_interface/EffortJointInterface</hardwareInterface>
        <mechanicalReduction>1</mechanicalReduction>
      </actuator>
    </transmission>
   
  </xacro:macro>

    <xacro:macro name="arm_wheel" params="fb lr parent translateX translateY translateZ flipY"> <!--fb : front, back ; lr: left, right -->
    <link name="${fb}_${lr}_wheel">
      <visual>
        <origin xyz="0 ${-flipY*0.015} 0" rpy="${flipY*M_PI/2} 0  ${flipY*M_PI/2}" /> 
        <geometry>
          <mesh filename="package://shadow-bot/meshes/dae/frontWheel.dae"/>
        </geometry>
      </visual>
      <collision>
        <origin xyz="0 ${-flipY*0.015} 0" rpy="${flipY*M_PI/2} 0 0 " />
        <geometry>
          <cylinder length="${arm_wheel_height}" radius="${arm_wheel_radius}" />
        </geometry>
        <surface>
          <friction>
            <ode>
              <mu>1.0</mu>
              <mu2>0.25</mu2>
              <fdir1>1 0 0</fdir1>
              <slip1>0</slip1>
              <slip2>0</slip2>
            </ode>
            <torsional>
              <coefficient>0.0</coefficient>
              <patch_radius>0</patch_radius>
              <surface_radius>0</surface_radius>
              <use_patch_radius>1</use_patch_radius>
              <ode>
                <slip>0</slip>
              </ode>
            </torsional>
          </friction>
          <bounce>
            <restitution_coefficient>1</restitution_coefficient>
            <threshold>1e+06</threshold>
          </bounce>
          <contact>
            <collide_without_contact>0</collide_without_contact>
            <collide_without_contact_bitmask>1</collide_without_contact_bitmask>
            <collide_bitmask>1</collide_bitmask>
            <ode>
              <soft_cfm>0</soft_cfm>
              <soft_erp>0.2</soft_erp>
              <kp>1e+13</kp>
              <kd>1</kd>
              <max_vel>0.01</max_vel>
              <min_depth>0</min_depth>
            </ode>
            <bullet>
              <split_impulse>1</split_impulse>
              <split_impulse_penetration_threshold>-0.01</split_impulse_penetration_threshold>
              <soft_cfm>0</soft_cfm>
              <soft_erp>0.2</soft_erp>
              <kp>1e+13</kp>
              <kd>1</kd>
            </bullet>
          </contact>     
        </surface>
      </collision>
      <inertial>
        <mass value="${arm_wheel_mass}" />
        <origin xyz="0 0 0" rpy="${flipY*M_PI/2} 0 0 " />
        <cylinder_inertia  m="${arm_wheel_mass}" r="${arm_wheel_radius}" h="${arm_wheel_height}" />
      </inertial>
    </link>

    <gazebo reference="${fb}_${lr}_wheel">
      <turnGravityOff>false</turnGravityOff>
    </gazebo>

    <joint name="${fb}_${lr}_wheel_joint" type="continuous">
      <parent link="${parent}"/>
      <child link="${fb}_${lr}_wheel"/>
      <origin xyz="${translateX} ${translateY} ${translateZ}" rpy="0 0 0" /> 
      <axis xyz="0 1 0" rpy="0  0" />
      <limit effort="10000" velocity="10000"/>
      <joint_properties damping="0.0" friction="0.0"/>
    </joint>

    <!-- Transmission is important to link the joints and the controller -->
    <transmission name="${fb}_${lr}_wheel_joint_trans">
      <type>transmission_interface/SimpleTransmission</type>
      <joint name="${fb}_${lr}_wheel_joint">
        <hardwareInterface>hardware_interface/EffortJointInterface</hardwareInterface>
      </joint>
      <actuator name="${fb}_${lr}_wheel_joint_motor">
        <hardwareInterface>hardware_interface/EffortJointInterface</hardwareInterface>
        <mechanicalReduction>1</mechanicalReduction>
      </actuator>
    </transmission>
   
  </xacro:macro>
</robot>
